<?xml version="1.0"?>
<sdf version="1.6">
  <model name='quadrotor'>
    <static>False</static>
    <link name ='pixhawk'>
      <pose>0 0 0 0 0 0</pose>
      <collision name="collision">
        <geometry>
          <mesh>
            <uri>model://quadrotor/meshes/pixhawk.dae</uri>
            <scale>1 1 1</scale>
          </mesh>
        </geometry>
        <surface>
          <contact>
            <collide_bitmask>0xffff</collide_bitmask>
          </contact>
          <friction>
            <ode>
              <mu>100</mu>
              <mu2>50</mu2>
            </ode>
          </friction>
        </surface>
      </collision>
      <visual name="visual">
        <geometry>
          <mesh>
            <uri>model://quadrotor/meshes/pixhawk.dae</uri>
            <scale>1 1 1</scale>
          </mesh>
        </geometry>
      </visual>
    </link>
    <link name ='base_plate'>
      <pose>0.5 0 0 0 0 0</pose>
      <collision name="collision">
        <geometry>
          <mesh>
            <uri>model://quadrotor/meshes/baSE_plate.dae</uri>
            <scale>1 1 1</scale>
          </mesh>
        </geometry>
        <surface>
          <contact>
            <collide_bitmask>0xffff</collide_bitmask>
          </contact>
          <friction>
            <ode>
              <mu>100</mu>
              <mu2>50</mu2>
            </ode>
          </friction>
        </surface>
      </collision>
      <visual name="visual">
        <geometry>
          <mesh>
            <uri>model://quadrotor/meshes/baSE_plate.dae</uri>
            <scale>1 1 1</scale>
          </mesh>
        </geometry>
      </visual>
    </link>
    <link name ='battery'>
      <pose>0.5 0 0 0 0 0</pose>
      <collision name="collision">
        <geometry>
          <mesh>
            <uri>model://quadrotor/meshes/battery_pack.dae</uri>
            <scale>1 1 1</scale>
          </mesh>
        </geometry>
        <surface>
          <contact>
            <collide_bitmask>0xffff</collide_bitmask>
          </contact>
          <friction>
            <ode>
              <mu>100</mu>
              <mu2>50</mu2>
            </ode>
          </friction>
        </surface>
      </collision>
      <visual name="visual">
        <geometry>
          <mesh>
            <uri>model://quadrotor/meshes/battery_pack.dae</uri>
            <scale>1 1 1</scale>
          </mesh>
        </geometry>
      </visual>
    </link>
    <link name ='jetson'>
      <pose>1 0 0 0 0 0</pose>
      <collision name="collision">
        <geometry>
          <mesh>
            <uri>model://quadrotor/meshes/jetson.dae</uri>
            <scale>1 1 1</scale>
          </mesh>
        </geometry>
        <surface>
          <contact>
            <collide_bitmask>0xffff</collide_bitmask>
          </contact>
          <friction>
            <ode>
              <mu>100</mu>
              <mu2>50</mu2>
            </ode>
          </friction>
        </surface>
      </collision>
      <visual name="visual">
        <geometry>
          <mesh>
            <uri>model://quadrotor/meshes/jetson.dae</uri>
            <scale>1 1 1</scale>
          </mesh>
        </geometry>
      </visual>
    </link>
    <link name ='propeller'>
      <pose>1.5 0 0 0 0 0</pose>
      <collision name="collision">
        <geometry>
          <mesh>
            <uri>model://quadrotor/meshes/prop.dae</uri>
            <scale>1 1 1</scale>
          </mesh>
        </geometry>
        <surface>
          <contact>
            <collide_bitmask>0xffff</collide_bitmask>
          </contact>
          <friction>
            <ode>
              <mu>100</mu>
              <mu2>50</mu2>
            </ode>
          </friction>
        </surface>
      </collision>
      <visual name="visual">
        <material>
          <script>
            <name>Gazebo/Yellow</name>
            <uri>file://media/materials/scripts/gazebo.material</uri>
          </script>
          <shader type='pixel'/>
        </material>
        <geometry>
          <mesh>
            <uri>model://quadrotor/meshes/prop.dae</uri>
            <scale>1 1 1</scale>
          </mesh>
        </geometry>
      </visual>
    </link>
    <link name ='struct_rod'>
      <pose>2.0 0 0 0 0 0</pose>
      <collision name="collision">
        <geometry>
          <mesh>
            <uri>model://quadrotor/meshes/Struct_rod.dae</uri>
            <scale>1 1 1</scale>
          </mesh>
        </geometry>
        <surface>
          <contact>
            <collide_bitmask>0xffff</collide_bitmask>
          </contact>
          <friction>
            <ode>
              <mu>100</mu>
              <mu2>50</mu2>
            </ode>
          </friction>
        </surface>
      </collision>
      <visual name="visual">
        <geometry>
          <mesh>
            <uri>model://quadrotor/meshes/Struct_rod.dae</uri>
            <scale>1 1 1</scale>
          </mesh>
        </geometry>
      </visual>
    </link>
    <link name ='top_cover'>
      <pose>2.5 0 0 0 0 0</pose>
      <collision name="collision">
        <geometry>
          <mesh>
            <uri>model://quadrotor/meshes/top_cover.dae</uri>
            <scale>1 1 1</scale>
          </mesh>
        </geometry>
        <surface>
          <contact>
            <collide_bitmask>0xffff</collide_bitmask>
          </contact>
          <friction>
            <ode>
              <mu>100</mu>
              <mu2>50</mu2>
            </ode>
          </friction>
        </surface>
      </collision>
      <visual name="visual">
        <geometry>
          <mesh>
            <uri>model://quadrotor/meshes/top_cover.dae</uri>
            <scale>1 1 1</scale>
          </mesh>
        </geometry>
      </visual>
    </link>

    <joint name="test" type="revolute">
      <pose> 0.25 0 0 0 0 0</pose>
      <parent>struct_rod</parent>
      <child>propeller</child>
      <axis>
        <limit>
          <lower>-0.4</lower>
          <upper>0.4</upper>
        </limit>
        <xyz>0 1 0</xyz>
      </axis>
    </joint>  
  </model>
</sdf>