<?xml version='1.0'?>
<sdf version='1.6'>
  <model name='table'>
    <plugin name='joint_plugin' filename='libiarc_state_plugins_joint_plugin.so' >
      <joint_name>radar_mast</joint_name>
      <angular_speed>1</angular_speed>
    </plugin>
    <plugin name="dipole_magnet_1" filename="libiarc_magnet_plugin.so">
      <bodyName>magnet_1</bodyName>
      <Id>1</Id>
      <dipole_moment>0 0 0.739859</dipole_moment>
      <!-- Set to false if not using ROS -->
      <shouldPublish>true</shouldPublish>
      <topicNs>magnetic_force/mast/magnet_1</topicNs>
      <updateRate>100</updateRate>
    </plugin>
    <plugin name="dipole_magnet_2" filename="libiarc_magnet_plugin.so">
      <bodyName>magnet_2</bodyName>
      <Id>2</Id>
      <dipole_moment>0 0 0.739859</dipole_moment>
      <!-- Set to false if not using ROS -->
      <shouldPublish>true</shouldPublish>
      <topicNs>magnetic_force/mast/magnet_2</topicNs>
      <updateRate>100</updateRate>
    </plugin>
    <link name='magnet_1'>
      <inertial>
        <mass>1</mass>
        <inertia>
          <ixx>0.145833</ixx>
          <ixy>0</ixy>
          <ixz>0</ixz>
          <iyy>0.145833</iyy>
          <iyz>0</iyz>
          <izz>0.125</izz>
        </inertia>
        <pose>0 0 0 0 -0 0</pose>
      </inertial>
      <self_collide>0</self_collide>
      <enable_wind>0</enable_wind>
      <kinematic>0</kinematic>
      <pose >-0.004854 -0.129396 1.407488 0.003418 -1.572042 -4.696979</pose>
      <gravity>1</gravity>
      <visual name='visual'>
        <geometry>
          <cylinder>
            <radius>0.003968</radius>
            <length>0.0127</length>
          </cylinder>
        </geometry>
        <material>
          <script>
            <name>Gazebo/Grey</name>
            <uri>file://media/materials/scripts/gazebo.material</uri>
          </script>
        </material>
        <pose>0 0 0 0 -0 0</pose>
        <transparency>0</transparency>
        <cast_shadows>1</cast_shadows>
      </visual>
      <collision name='collision'>
        <pose>0 0 0 0 0 0</pose>
        <geometry>
          <cylinder>
            <radius>0.003968</radius>
            <length>0.0127</length>
          </cylinder>
        </geometry>
      </collision>
    </link>
    <link name='magnet_2'>
      <inertial>
        <mass>1</mass>
        <inertia>
          <ixx>0.145833</ixx>
          <ixy>0</ixy>
          <ixz>0</ixz>
          <iyy>0.145833</iyy>
          <iyz>0</iyz>
          <izz>0.125</izz>
        </inertia>
        <pose>0 0 0 0 -0 0</pose>
      </inertial>
      <self_collide>0</self_collide>
      <enable_wind>0</enable_wind>
      <kinematic>0</kinematic>
      <pose>-0.004854 -0.116651 1.407488 0.003418 -1.572042 -4.696979</pose>
      <gravity>1</gravity>
      <visual name='visual'>
        <geometry>
          <cylinder>
            <radius>0.003968</radius>
            <length>0.0127</length>
          </cylinder>
        </geometry>
        <material>
          <script>
            <name>Gazebo/Grey</name>
            <uri>file://media/materials/scripts/gazebo.material</uri>
          </script>
        </material>
        <pose>0 0 0 0 -0 0</pose>
        <transparency>0</transparency>
        <cast_shadows>1</cast_shadows>
      </visual>
      <collision name='collision'>
        <pose>0 0 0 0 0 0</pose>
        <geometry>
          <cylinder>
            <radius>0.003968</radius>
            <length>0.0127</length>
          </cylinder>
        </geometry>
      </collision>
    </link>
    <static>1</static>
    <link name='table'>
      <inertial>
        <mass>3000</mass>
        <inertia>
          <ixx>2271</ixx>
          <ixy>0</ixy>
          <ixz>0</ixz>
          <iyy>8521</iyy>
          <iyz>0</iyz>
          <izz>10417</izz>
        </inertia>
        <pose>0 0 0 0 -0 0.0</pose>
      </inertial>
      <self_collide>0</self_collide>
      <enable_wind>0</enable_wind>
      <kinematic>0</kinematic>
      <pose>0 0 0 0 -0 0</pose>
      <visual name='visual'>
        <geometry>
          <box>
            <size>5 2.5 0.75</size>
          </box>
        </geometry>
        <material>
          <script>
            <name>Gazebo/Grey</name>
            <uri>file://media/materials/scripts/gazebo.material</uri>
          </script>
          <shader type='pixel'/>
        </material>
        <pose>0 0 0 0 -0 0</pose>
        <transparency>0</transparency>
        <cast_shadows>1</cast_shadows>
      </visual>
      <collision name='collision'>
        <laser_retro>0</laser_retro>
        <max_contacts>10</max_contacts>
        <pose>0 0 0 0 -0 0</pose>
        <geometry>
          <box>
            <size>5 2.5 0.75</size>
          </box>
        </geometry>
        <surface>
          <friction>
            <ode>
              <mu>1</mu>
              <mu2>1</mu2>
              <fdir1>0 0 0</fdir1>
              <slip1>0</slip1>
              <slip2>0</slip2>
            </ode>
            <torsional>
              <coefficient>1</coefficient>
              <patch_radius>0</patch_radius>
              <surface_radius>0</surface_radius>
              <use_patch_radius>1</use_patch_radius>
              <ode>
                <slip>0</slip>
              </ode>
            </torsional>
          </friction>
          <bounce>
            <restitution_coefficient>0</restitution_coefficient>
            <threshold>1e+06</threshold>
          </bounce>
          <contact>
            <collide_without_contact>0</collide_without_contact>
            <collide_without_contact_bitmask>1</collide_without_contact_bitmask>
            <collide_bitmask>1</collide_bitmask>
            <ode>
              <soft_cfm>0</soft_cfm>
              <soft_erp>0.2</soft_erp>
              <kp>1e+13</kp>
              <kd>1</kd>
              <max_vel>0.01</max_vel>
              <min_depth>0</min_depth>
            </ode>
            <bullet>
              <split_impulse>1</split_impulse>
              <split_impulse_penetration_threshold>-0.01</split_impulse_penetration_threshold>
              <soft_cfm>0</soft_cfm>
              <soft_erp>0.2</soft_erp>
              <kp>1e+13</kp>
              <kd>1</kd>
            </bullet>
          </contact>
        </surface>
      </collision>
    </link>

    <include>
      <uri>model://mast</uri>
      <pose>-0.215 -0.245 0.375 0 0 -1.57</pose>
    </include>

    <include>
      <uri>model://gun</uri>
      <pose>1 0.75 0.375 0 -0 0.7854</pose>
      <name>gun_back_left</name>
    </include>

    <include>
      <uri>model://gun</uri>
      <pose>-1 0.75 0.375 0 -0 2.3562</pose>
      <name>gun_back_right</name>
    </include>

    <include>
      <uri>model://gun</uri>
      <pose>1 -0.75 0.375 0 0 -0.7854</pose>
      <name>gun_front_left</name>
    </include>

    <include>
      <uri>model://gun</uri>
      <pose>-1 -0.75 0.375 0 -0 -2.35618</pose>
      <name>gun_front_right</name>
    </include>

    <include>
      <uri>model://dish</uri>
      <pose>2 0 0.375 0 -0 1.57</pose>
      <name>dish_left</name>
    </include>

    <include>
      <uri>model://dish</uri>
      <pose>-2 0 0.375 0 -0 -1.57</pose>
      <name>dish_right</name>
    </include>

    <include>
      <uri>model://led_light_green</uri>
      <pose>0.439841 -0.044478 1.6375 0 0 -1.57</pose>
    </include>

    <include>
      <uri>model://led_light_red</uri>
      <pose>-0.490159 -0.045219 1.6375 0 0 -1.57</pose>
    </include>

    <include>
      <uri>model://flag</uri>
      <pose>0.75 0 0.375 0 -0 0</pose>
    </include>

    <include>
      <uri>model://radar</uri>
      <pose>-0.0075 0.505 1.925 0 -0 0</pose>
    </include>

    <joint name='radar_mast' type='revolute' >
      <parent>mast::link</parent>
      <child>radar::link</child>
      <pose>0 -0.500 0 0 0 0</pose>
      <axis>
        <xyz>0 0 1</xyz>
      </axis>
    </joint>

    <joint name='mast_table' type='fixed' >
      <parent>table</parent>
      <child>mast::link</child>
    </joint>

    <joint name='dish_left_table' type='fixed' >
      <parent>table</parent>
      <child>dish_left::link</child>
    </joint>

    <joint name='dish_right_table' type='fixed' >
      <parent>table</parent>
      <child>dish_right::link</child>
    </joint>

    <joint name='flag_table' type='fixed' >
      <parent>table</parent>
      <child>flag::link</child>
    </joint>

    <joint name='gun_back_left_table' type='fixed' >
      <parent>table</parent>
      <child>gun_back_left::link</child>
    </joint>

    <joint name='gun_back_right_table' type='fixed' >
      <parent>table</parent>
      <child>gun_back_right::link</child>
    </joint>

    <joint name='gun_front_left_table' type='fixed' >
      <parent>table</parent>
      <child>gun_front_left::link</child>
    </joint>

    <joint name='gun_front_right_table' type='fixed' >
      <parent>table</parent>
      <child>gun_front_right::link</child>
    </joint>

    <joint name='led_light_red_table' type='fixed' >
      <parent>table</parent>
      <child>led_light_red::link</child>
    </joint>

    <joint name='led_light_green_table' type='fixed' >
      <parent>table</parent>
      <child>led_light_green::link</child>
    </joint>

  </model>

</sdf>
