<?xml version="1.0"?>
<sdf version="1.6">
    <model name="grabber">
        <link name="palm">
            <pose>0.0 0.0 0.05 0 0 0</pose>
            <inertial>
                <inertia>
                    <ixx>0.000189</ixx>
                    <ixy>0</ixy>
                    <ixz>0</ixz>
                    <iyy>0.000010</iyy>
                    <iyz>0</iyz>
                    <izz>0.000189</izz>
                </inertia>
                <mass>0.0985</mass>
            </inertial>
            <collision name="collision">
                <geometry>
                    <box>
                        <size>0.025 0.15 0.025</size>
                    </box>
                </geometry>
            </collision>
            <visual name="visual">
                <geometry>
                    <box>
                        <size>0.025 0.15 0.025</size>
                    </box>
                </geometry>
                <material>
                    <script>Gazebo/Red</script>
                </material>
            </visual>
        </link>
        <link name="left_finger">
            <pose>0.06 0.05 0.05 0 0 -1.57</pose>
            <inertial>
                <inertia>
                    <ixx>0.000020</ixx>
                    <ixy>0</ixy>
                    <ixz>0</ixz>
                    <iyy>0.0000008859</iyy>
                    <iyz>0</iyz>
                    <izz>0.000020</izz>
                </inertia>
                <mass>0.023625</mass>
            </inertial>
            <collision name="collision">
                <geometry>
                    <box>
                        <size>0.015 0.1 0.015</size>
                    </box>
                </geometry>
            </collision>
            <visual name="visual">
                <geometry>
                    <box>
                        <size>0.015 0.1 0.015</size>
                    </box>
                </geometry>
                <material>
                    <script>Gazebo/Blue</script>
                </material>
            </visual>
        </link>
        <link name="right_finger">
            <pose>0.06 -0.05 0.05 0 0 -1.57</pose>
            <inertial>
                <inertia>
                    <ixx>0.000020</ixx>
                    <ixy>0</ixy>
                    <ixz>0</ixz>
                    <iyy>0.0000008859</iyy>
                    <iyz>0</iyz>
                    <izz>0.000020</izz>
                </inertia>
                <mass>0.023625</mass>
            </inertial>
            <collision name="collision">
                <geometry>
                    <box>
                        <size>0.015 0.1 0.015</size>
                    </box>
                </geometry>
            </collision>
            <visual name="visual">
                <geometry>
                    <box>
                        <size>0.015 0.1 0.015</size>
                    </box>
                </geometry>
                <material>
                    <script>Gazebo/Blue</script>
                </material>
            </visual>
        </link>
        <joint name="right_hand" type="prismatic">
            <child>palm</child>
            <parent>right_finger</parent>
            <axis>
                <limit>
                    <lower>0</lower>
                    <upper>0.9</upper>
                </limit>
                <xyz>0 -1 0</xyz>
            </axis>
        </joint>
        <joint name="left_hand" type="prismatic">
            <child>palm</child>
            <parent>left_finger</parent>
            <axis>
                <limit>
                    <lower>0</lower>
                    <upper>0.9</upper>
                </limit>
                <xyz>0 1 0</xyz>
            </axis>
        </joint>
    </model>
</sdf>