<?xml version="1.0"?>
<sdf version="1.6">
    <model name="grabber">
        
        <link name="riser">
            <pose>-0.1 0.0 0.5 0 0 0</pose>
            <inertial>
                <pose>0 0 -0.5 0 0 0</pose>
                <inertia>
                    <ixx>0.01</ixx>
                    <ixy>0</ixy>
                    <ixz>0</ixz>
                    <iyy>0.01</iyy>
                    <iyz>0</iyz>
                    <izz>0.01</izz>
                </inertia>
                <mass>10.0</mass>
            </inertial>
            <collision name="collision">
                <geometry>
                    <box>
                        <size>0.2 0.2 1.0</size>
                    </box>
                </geometry>
            </collision>
            <visual name="visual">
                <geometry>
                    <box>
                        <size>0.2 0.2 1.0</size>
                    </box>
                </geometry>
                <material>
                    <script>Gazebo/Purple</script>
                </material>
            </visual>
        </link>

        <link name="palm">
            <pose>0.0 0.0 0.05 0 0 0</pose>
            <inertial>
                <inertia>
                    <ixx>0.000189</ixx>
                    <ixy>0</ixy>
                    <ixz>0</ixz>
                    <iyy>0.000010</iyy>
                    <iyz>0</iyz>
                    <izz>0.000189</izz>
                </inertia>
                <mass>0.0985</mass>
            </inertial>
            <collision name="collision">
                <geometry>
                    <box>
                        <size>0.025 0.15 0.025</size>
                    </box>
                </geometry>
                <surface>
                    <contact>
                        <collide_bitmask>0xffff</collide_bitmask>
                    </contact>
                    <friction>
                        <ode>
                        <mu>100</mu>
                        <mu2>50</mu2>
                        </ode>
                    </friction>
                </surface>
            </collision>
            <visual name="visual">
                <geometry>
                    <box>
                        <size>0.025 0.15 0.025</size>
                    </box>
                </geometry>
                <material>
                    <script>Gazebo/Red</script>
                </material>
            </visual>
        </link>
        <link name="left_finger">
            <pose>0.0628 0.05 0.05 0 0 -1.57</pose>
            <inertial>
                <inertia>
                    <ixx>0.000020</ixx>
                    <ixy>0</ixy>
                    <ixz>0</ixz>
                    <iyy>0.0000008859</iyy>
                    <iyz>0</iyz>
                    <izz>0.000020</izz>
                </inertia>
                <mass>0.023625</mass>
            </inertial>
            <collision name="collision">
                <geometry>
                    <box>
                        <size>0.015 0.1 0.015</size>
                    </box>
                </geometry>
                <surface>
                    <contact>
                        <collide_bitmask>0xffff</collide_bitmask>
                    </contact>
                    <friction>
                        <ode>
                        <mu>100</mu>
                        <mu2>50</mu2>
                        </ode>
                    </friction>
                </surface>
            </collision>
            <visual name="visual">
                <geometry>
                    <box>
                        <size>0.015 0.1 0.015</size>
                    </box>
                </geometry>
                <material>
                    <script>Gazebo/Blue</script>
                </material>
            </visual>
        </link>
        <link name="right_finger">
            <pose>0.0628 -0.05 0.05 0 0 -1.57</pose>
            <inertial>
                <inertia>
                    <ixx>0.000020</ixx>
                    <ixy>0</ixy>
                    <ixz>0</ixz>
                    <iyy>0.0000008859</iyy>
                    <iyz>0</iyz>
                    <izz>0.000020</izz>
                </inertia>
                <mass>0.023625</mass>
            </inertial>
            <collision name="collision">
                <geometry>
                    <box>
                        <size>0.015 0.1 0.015</size>
                    </box>
                </geometry>
                <surface>
                    <contact>
                        <collide_bitmask>0xffff</collide_bitmask>
                    </contact>
                    <friction>
                        <ode>
                        <mu>100</mu>
                        <mu2>50</mu2>
                        </ode>
                    </friction>
                </surface>
            </collision>
            <visual name="visual">
                <geometry>
                    <box>
                        <size>0.015 0.1 0.015</size>
                    </box>
                </geometry>
                <material>
                    <script>Gazebo/Blue</script>
                </material>
            </visual>
        </link>
        <joint name="right_hand" type="prismatic">
            <parent>right_finger</parent>
            <child>palm</child>
            <axis>
                <limit>
                    <lower>0</lower>
                    <upper>0.04</upper>
                    <velocity>0.01</velocity>
                </limit>
                <xyz>0 -1 0</xyz>
            </axis>
        </joint>
        <joint name="left_hand" type="prismatic">
            <parent>left_finger</parent>
            <child>palm</child>
            <axis>
                <limit>
                    <lower>0</lower>
                    <upper>0.04</upper>
                    <velocity>0.01</velocity>
                </limit>
                <xyz>0 1 0</xyz>
            </axis>
        </joint>

        <joint name="tester" type="prismatic">
            <parent>riser</parent>
            <child>palm</child>
            <axis>
                <limit>
                    <lower>0</lower>
                    <upper>0.9</upper>
                    <!-- <velocity>0.01</velocity> -->
                </limit>
                <xyz>0 0 1</xyz>
            </axis>
        </joint>


        <plugin name="grabber_plugin" filename="libiarc_grabber_plugin.so">
            <namespace>firefly</namespace>
            <link_name1>right_finger</link_name1>
            <link_name2>left_finger</link_name2>
            <force_magnitude>10</force_magnitude>
        </plugin>
    </model>
</sdf>