<?xml version="1.0" ?>
<sdf version="1.6">
  <model name="quadplane">
  <plugin filename="libGPS_plugin.so" name="quadplane_GPS">
      <namespace>quadplane</namespace>
      <linkName>plane</linkName>
    </plugin>
    <plugin filename="libimu_plugin.so" name="quadplane_imu">
      <namespace>quadplane</namespace>
      <linkName>plane</linkName>
    </plugin>
    <plugin filename="libairspeed_plugin.so" name="quadrotor_airspeed_sensor">
      <namespace>quadplane</namespace>
      <linkName>plane</linkName>
    </plugin>
    <plugin filename="libbarometer_plugin.so" name="quadplane_barometer">
      <namespace>quadplane</namespace>
      <linkName>plane</linkName>
    </plugin>
    <plugin filename="libaircraft_truth_plugin.so" name="${namespace}_aircraft_truth_plugin">
      <namespace>quadplane</namespace>
      <linkName>plane</linkName>
    </plugin>
    <plugin filename="libaircraft_forces_and_moments_plugin.so" name="quadplane_aircraft_forces_and_moments">
        <linkName>plane</linkName>
        <namespace>quadplane</namespace>
    </plugin>
    
    <static>false</static>
      <link name='front_propeller'>
        <pose>0 0 0 -1.57 0 0</pose>
        <inertial>
          <pose>0.000102 0.000117 0.014206 0 0 0</pose>
          <mass>0.07</mass>
          <inertia>
            <ixx>7.1513e-07</ixx>
            <ixy>0</ixy>
            <ixz>0</ixz>
            <iyy>7.1522e-07</iyy>
            <iyz>0</iyz>
            <izz>1.42218e-06</izz>
          </inertia>
        </inertial>
        <collision name="collision">
          <geometry>
            <mesh>
              <uri>model://quadplane/meshes/front_prop.dae</uri>
              <scale>1 1 1</scale>
            </mesh>
          </geometry>
          <surface>
            <contact>
              <collide_bitmask>0xffff</collide_bitmask>
            </contact>
            <friction>
              <ode>
                <mu>100</mu>
                <mu2>50</mu2>
              </ode>
            </friction>
          </surface>
        </collision>
        <visual name='visual'>
          <geometry>
            <mesh>
              <uri>model://quadplane/meshes/front_prop.dae</uri>
              <scale>1 1 1</scale>
            </mesh>
          </geometry>
        </visual>
      </link>


    <link name ='top_propeller1'>
      <pose>1.4142 -0.4627 0.03 0 0 0</pose>
        <inertial>
          <pose>0.000102 0.000117 0.014206 0 0 0</pose>
          <mass>0.08</mass>
          <inertia>
            <ixx>7.1513e-07</ixx>
            <ixy>0</ixy>
            <ixz>0</ixz>
            <iyy>7.1522e-07</iyy>
            <iyz>0</iyz>
            <izz>1.42218e-06</izz>
          </inertia>
        </inertial>
      <collision name="collision">
        <geometry>
          <mesh>
            <uri>model://quadplane/meshes/top_props.dae</uri>
            <scale>1 1 1</scale>
          </mesh>
        </geometry>
        <surface>
          <contact>
            <collide_bitmask>0xffff</collide_bitmask>
          </contact>
          <friction>
            <ode>
              <mu>100</mu>
              <mu2>50</mu2>
            </ode>
          </friction>
        </surface>
      </collision>
      <visual name="visual">
        <material>
          <script>
            <name>Gazebo/Green</name>
            <uri>file://media/materials/scripts/gazebo.material</uri>
          </script>
          <shader type='pixel'/>
        </material>  
        <geometry>
          <mesh>
            <uri>model://quadplane/meshes/top_props.dae</uri>
            <scale>1 1 1</scale>
          </mesh>
        </geometry>
      </visual>
    </link>


    <link name ='top_propeller2'>
      <pose>1.4142 0.4627 0.03 0 0 0</pose>
        <inertial>
          <pose>0.000102 0.000117 0.014206 0 0 0</pose>
          <mass>0.08</mass>
          <inertia>
            <ixx>7.1513e-07</ixx>
            <ixy>0</ixy>
            <ixz>0</ixz>
            <iyy>7.1522e-07</iyy>
            <iyz>0</iyz>
            <izz>1.42218e-06</izz>
          </inertia>
        </inertial>
      <collision name="collision">
        <geometry>
          <mesh>
            <uri>model://quadplane/meshes/top_props.dae</uri>
            <scale>1 1 1</scale>
          </mesh>
        </geometry>
        <surface>
          <contact>
            <collide_bitmask>0xffff</collide_bitmask>
          </contact>
          <friction>
            <ode>
              <mu>100</mu>
              <mu2>50</mu2>
            </ode>
          </friction>
        </surface>
      </collision>
      <visual name="visual">
        <material>
          <script>
            <name>Gazebo/Green</name>
            <uri>file://media/materials/scripts/gazebo.material</uri>
          </script>
          <shader type='pixel'/>
        </material>  
        <geometry>
          <mesh>
            <uri>model://quadplane/meshes/top_props.dae</uri>
            <scale>1 1 1</scale>
          </mesh>
        </geometry>
      </visual>
    </link>

    <link name ='top_propeller3'>
      <pose>0.37 -0.4627 0.03 0 0 0</pose>
        <inertial>
          <pose>0.000102 0.000117 0.014206 0 0 0</pose>
          <mass>0.08</mass>
          <inertia>
            <ixx>7.1513e-07</ixx>
            <ixy>0</ixy>
            <ixz>0</ixz>
            <iyy>7.1522e-07</iyy>
            <iyz>0</iyz>
            <izz>1.42218e-06</izz>
          </inertia>
        </inertial>
      <collision name="collision">
        <geometry>
          <mesh>
            <uri>model://quadplane/meshes/top_props.dae</uri>
            <scale>1 1 1</scale>
          </mesh>
        </geometry>
        <surface>
          <contact>
            <collide_bitmask>0xffff</collide_bitmask>
          </contact>
          <friction>
            <ode>
              <mu>100</mu>
              <mu2>50</mu2>
            </ode>
          </friction>
        </surface>
      </collision>
      <visual name="visual">
        <material>
          <script>
            <name>Gazebo/Green</name>
            <uri>file://media/materials/scripts/gazebo.material</uri>
          </script>
          <shader type='pixel'/>
        </material>  
        <geometry>
          <mesh>
            <uri>model://quadplane/meshes/top_props.dae</uri>
            <scale>1 1 1</scale>
          </mesh>
        </geometry>
      </visual>
    </link>

    <link name ='top_propeller4'>
      <pose>0.37 0.4627 0.03 0 0 0</pose>
        <inertial>
          <pose>0.000102 0.000117 0.014206 0 0 0</pose>
          <mass>0.08</mass>
          <inertia>
            <ixx>7.1513e-07</ixx>
            <ixy>0</ixy>
            <ixz>0</ixz>
            <iyy>7.1522e-07</iyy>
            <iyz>0</iyz>
            <izz>1.42218e-06</izz>
          </inertia>
        </inertial>
      <collision name="collision">
        <geometry>
          <mesh>
            <uri>model://quadplane/meshes/top_props.dae</uri>
            <scale>1 1 1</scale>
          </mesh>
        </geometry>
        <surface>
          <contact>
            <collide_bitmask>0xffff</collide_bitmask>
          </contact>
          <friction>
            <ode>
              <mu>100</mu>
              <mu2>50</mu2>
            </ode>
          </friction>
        </surface>
      </collision>
      <visual name="visual">
        <material>
          <script>
            <name>Gazebo/Green</name>
            <uri>file://media/materials/scripts/gazebo.material</uri>
          </script>
          <shader type='pixel'/>
        </material>  
        <geometry>
          <mesh>
            <uri>model://quadplane/meshes/top_props.dae</uri>
            <scale>1 1 1</scale>
          </mesh>
        </geometry>
      </visual>
    </link>


    <link name ='plane'>
      <pose>0 0 0 0 0 0</pose>
        <inertial>
          <pose>-0.000015 0.878954 0.013308 0 0 0</pose>
          <mass>10.58</mass>
          <inertia>
            <ixx>0.015947</ixx>
            <ixy>0.000003</ixy>
            <ixz>0</ixz>
            <iyy>0.013663</iyy>
            <iyz>-0.000276</iyz>
            <izz>0.029280 </izz>
          </inertia>
        </inertial>
      <collision name="collision">
        <geometry>
          <mesh>
            <uri>model://quadplane/meshes/plane.dae</uri>
            <scale>1 1 1</scale>
          </mesh>
        </geometry>
        <surface>
          <contact>
            <collide_bitmask>0xffff</collide_bitmask>
          </contact>
          <friction>
            <ode>
              <mu>100</mu>
              <mu2>50</mu2>
            </ode>
          </friction>
        </surface>
      </collision>
      <visual name="visual">
        <!-- <material>
          <script>
            <name>Gazebo/Black</name>
            <uri>file://media/materials/scripts/gazebo.material</uri>
          </script>
          <shader type='pixel'/>
        </material>   -->
        <geometry>
          <mesh>
            <uri>model://quadplane/meshes/plane.dae</uri>
            <scale>1 1 1</scale>
          </mesh>
        </geometry>
      </visual>
    </link>

    <joint name="front" type="revolute">
      <pose> 0 0 0 0 0 0</pose>
      <parent>plane</parent>
      <child>front_propeller</child>
      <axis>
        <!-- <limit>
          <lower>-0.4</lower>
          <upper>0.4</upper>
        </limit> -->
        <xyz>1 0 0</xyz>
      </axis>
    </joint> 

    <joint name="top4" type="revolute">
      <pose> 0 0 0 0 0 0</pose>
      <parent>plane</parent>
      <child>top_propeller4</child>
      <axis>
        <!-- <limit>
          <lower>-0.4</lower>
          <upper>0.4</upper>
        </limit> -->
        <xyz>0 0 1</xyz>
      </axis>
    </joint> 

    <joint name="top1" type="revolute">
      <pose> 0 0 0 0 0 0</pose>
      <parent>plane</parent>
      <child>top_propeller1</child>
      <axis>
        <!-- <limit>
          <lower>-0.4</lower>
          <upper>0.4</upper>
        </limit> -->
        <xyz>0 0 1</xyz>
      </axis>
    </joint> 

    <joint name="top2" type="revolute">
      <pose> 0 0 0 0 0 0</pose>
      <parent>plane</parent>
      <child>top_propeller2</child>
      <axis>
        <!-- <limit>
          <lower>-0.4</lower>
          <upper>0.4</upper>
        </limit> -->
        <xyz>0 0 1</xyz>
      </axis>
    </joint> 

    <joint name="top3" type="revolute">
      <pose> 0 0 0 0 0 0</pose>
      <parent>plane</parent>
      <child>top_propeller3</child>
      <axis>
        <!-- <limit>
          <lower>-0.4</lower>
          <upper>0.4</upper>
        </limit> -->
        <xyz>0 0 1</xyz>
      </axis>
    </joint>     


  </model>
</sdf>
